O bloco `try...catch` é uma estrutura fundamental para tratamento de erros em JavaScript. Ele permite que você escreva código que pode gerar exceções (erros) e trate esses erros de forma controlada, evitando que a aplicação seja interrompida de maneira inesperada. Esse mecanismo é essencial para garantir que, mesmo diante de erros imprevistos, seu programa continue funcionando ou, ao menos, forneça mensagens de erro informativas.

**Estrutura Básica**

A sintaxe básica é a seguinte:

```jsx
try {
  // Código que pode lançar uma exceção
} catch (erro) {
  // Código para manipular a exceção capturada
}

```

- **`try`**: Envolve o bloco de código onde erros podem ocorrer.
- **`catch`**: Captura e trata qualquer exceção lançada dentro do `try`; a variável (por exemplo, `erro`) contém as informações sobre o problema.

**Exemplo Simples**

Mesmo que, em JavaScript, a divisão por zero não gere uma exceção (retorna `Infinity`), o exemplo a seguir ilustra a estrutura do `try...catch`:

```jsx
try {
  let resultado = 10 / 0;
  console.log("Resultado:", resultado);
} catch (erro) {
  console.error("Ocorreu um erro:", erro.message);
}
```

Esse exemplo demonstra a ideia de encapsular um bloco de código que **poderia** gerar um erro.

**Exemplo com Função**

Imagine uma função que tente acessar uma propriedade de um objeto. Se o objeto for `undefined` ou `null`, o acesso gera um erro. Veja o exemplo:

```jsx
function acessarPropriedade(obj) {
  try {
    console.log(obj.propriedade);
  } catch (erro) {
    console.error("Erro ao acessar propriedade:", erro.message);
  }
}

acessarPropriedade(undefined);
```

Neste caso, a tentativa de acessar `obj.propriedade` causará uma exceção, que é capturada pelo `catch`, permitindo que o erro seja tratado sem interromper o fluxo do programa.

**O Bloco `finally`**

O bloco `finally` é opcional, mas extremamente útil. Ele é executado sempre, independentemente de uma exceção ter sido gerada no bloco `try` ou não, permitindo a realização de tarefas de limpeza ou operações finais, como fechar conexões ou liberar recursos.

```jsx
try {
  // Tenta executar um código que pode gerar uma exceção
  let resultado = 2 / a; // 'a' não está definida, logo, gera erro
} catch (erro) {
  console.error("Ocorreu um erro:", erro.message);
} finally {
  console.log("Bloco finally executado.");
}
```

Mesmo ocorrendo uma exceção, o código no bloco `finally` será executado, garantindo que certas ações sempre aconteçam.

**Lançando Erros com `throw`**

Além de capturar erros, você pode lançar exceções manualmente utilizando a palavra-chave `throw`. Essa técnica é útil para implementar validações ou sinalizar que uma condição inesperada ocorreu.

```jsx
function validarNumero(numero) {
  if (typeof numero !== 'number') {
    throw new TypeError("O argumento deve ser um número");
  }
}

try {
  validarNumero("não é um número");
} catch (erro) {
  console.error("Erro capturado:", erro.message);
}
```

Neste exemplo, a função `validarNumero` lança um erro se o argumento não for do tipo `number`. O erro é, então, capturado pelo bloco `catch`.

**Considerações Importantes**

- **Erros Síncronos**: O `try...catch` é eficaz para capturar erros que ocorrem de forma síncrona dentro do bloco `try`. Para operações assíncronas (como callbacks, setTimeout, ou operações com Promises sem async/await), é necessário utilizar outras estratégias de tratamento de erro.
- **Manutenção e Legibilidade**: Utilizar `try...catch` ajuda a tornar o código mais robusto e facilita a depuração, pois você pode centralizar o tratamento de erros e registrar informações importantes para a resolução de problemas.
- **Bloco `finally`**: Ideal para garantir a execução de determinadas ações, independentemente do sucesso ou falha da operação testada no `try`.

**Resumo Final**

- **`try`**: Envolve o código que pode lançar exceções.
- **`catch`**: Captura a exceção lançada no bloco `try` e permite que você trate o erro de forma apropriada.
- **`finally`**: Executa um bloco de código sempre, seja o bloco `try` executado com sucesso ou com erro.
- **`throw`**: Permite lançar exceções manualmente para sinalizar condições de erro.

Esse conjunto de ferramentas é vital para o desenvolvimento de código mais resiliente, prevenindo que erros inesperados "quebrem" a aplicação e fornecendo mecanismos eficazes para a depuração e manutenção do sistema.